Workbook

Sheet README
B2: Sasha's Corner — Finance Workbook (v4)
B3: Full recipe system. Change an ingredient price → every menu item cost and P&L number recalculates.
B6: Colour code
B7: Blue text | C7: Numbers YOU type in
B8: Black text | C8: Formulas — calculate automatically
B9: Yellow fill | C9: Key inputs you'll change often
B10: Orange fill | C10: Industry estimate — verify against your invoices
B11: Red fill | C11: Needs your clarification
B13: How data flows
B14: Ingredients tab | C14: Raw material cost per unit. Single source of truth for all prices.
B15: Recipes tab | C15: Every item × size pairing with its ingredient list. Cost = SUM(qty × cost-per-unit) via lookup.
B16: Menu Items tab | C16: Summary of all 175 items — pulls cost price from Recipes.
B17: Daily Sales | C17: Daily totals: Square card / Square cash / own cash. Own cash pulls from Cash Transactions.
B18: Cash Transactions | C18: Log each non-Square cash sale by item. Dropdowns from your menu.
B19: Expenses | C19: Everything the business spends money on.
B20: Monthly P&L | C20: 12-month matrix showing revenue, COGS, opex, profit per month + annual total.
B21: Yearly Summary | C21: YTD totals, trends, best/worst months, card-vs-cash split.
B22: Dashboard | C22: At-a-glance view: this month, YTD, progress to target.
B24: The most important thing to understand
B25: Base prices assume whole milk. | C25: If a customer swaps to oat/almond/coconut/soy they pay the +£0.50 upcharge (tracked via Square as 'Oat milk' or 'Coconut milk' add-on). Your extra cost is ~£0.25 per swap. Net extra profit ≈ £0.25 per alt-milk drink.
B27: Priority actions
B28: A | C28: Verify Ingredients — orange costs are estimates. Replace with invoice prices. Everything else recalculates.
B29: B | C29: Answer the 12 open questions in Sources & Assumptions (the red-flagged items).
B30: C | C30: Start logging Daily Sales + Cash Transactions + Expenses from tomorrow.
B31: D | C31: End of each month: glance at Monthly P&L row for that month. Any margin under 60% → investigate.
B32: E | C32: When you have time, fix the item-name typos in Square (they're documented in Sources & Assumptions).
B35: Data status (last updated 28 Apr 2026)
B36: Daily Sales | C36: Sep 2025 → Apr 2026 imported. Card sales for Sep-Mar are from Mettle Square deposits (date = deposit date, ~1 day after actual sale). April uses actual Square Dashboard data.
B37: Just Eat | C37: Delivery sales (£114.92 over 7 events) recorded in 'Square — cash' column with notes.
B38: Expenses | C38: All Mettle bank outflows imported and categorised. Personal-looking spend tagged 'Director drawings' in notes. Capital expenditure (setup/equipment) tagged similarly in 'Other' category.
B39: Director Account | C39: New tab tracking your £6,850 capital injections IN vs your drawings OUT. Not part of operating P&L.

Sheet Ingredients
B2: Ingredients — Master Price List
B3: Every raw material. Orange = estimate — REPLACE with YOUR invoice prices. All recipes and margins recalculate automatically.
B5: Ingredient | C5: Category | D5: Pack size | E5: Pack unit | F5: Pack cost (£) | G5: Cost per unit | H5: Unit | I5: Supplier / notes
B6: Whole milk | C6: Dairy | D6: 13.62 | E6: L | F6: 9.98 | G6: =IFERROR(F6/D6,0) -> 0.73274596 | H6: L | I6: Real invoice — 3.4L = £2.37
B7: Semi-skimmed milk | C7: Dairy | D7: 3.4 | E7: L | F7: 2.37 | G7: =IFERROR(F7/D7,0) -> 0.69705882 | H7: L | I7: Same as whole — assumed
B8: Oat milk (barista) | C8: Dairy alt | D8: 1 | E8: L | F8: 2.5 | G8: =IFERROR(F8/D8,0) -> 2.5 | H8: L | I8: Real invoice — alt-milk £2.50/L
B9: Almond milk (barista) | C9: Dairy alt | D9: 1 | E9: L | F9: 2.5 | G9: =IFERROR(F9/D9,0) -> 2.5 | H9: L | I9: Real invoice — alt-milk £2.50/L
B10: Soy milk (barista) | C10: Dairy alt | D10: 1 | E10: L | F10: 2.5 | G10: =IFERROR(F10/D10,0) -> 2.5 | H10: L | I10: Real invoice — alt-milk £2.50/L
B11: Coconut milk (barista) | C11: Dairy alt | D11: 1 | E11: L | F11: 2.5 | G11: =IFERROR(F11/D11,0) -> 2.5 | H11: L | I11: Real invoice — alt-milk £2.50/L
B12: Whipping cream | C12: Dairy | D12: 1 | E12: L | F12: 6.8 | G12: =IFERROR(F12/D12,0) -> 6.8 | H12: L | I12: ESTIMATE
B13: Coffee beans (house blend) | C13: Coffee | D13: 6 | E13: kg | F13: 97.5 | G13: =IFERROR(F13/D13,0) -> 16.25 | H13: kg | I13: Real invoice — £95 per 5kg
B14: Coffee beans (decaf) | C14: Coffee | D14: 1 | E14: kg | F14: 24 | G14: =IFERROR(F14/D14,0) -> 24 | H14: kg | I14: ESTIMATE
B15: Vanilla syrup (Monin) | C15: Syrup | D15: 1000 | E15: ml | F15: 5 | G15: =IFERROR(F15/D15,0) -> 0.005 | H15: ml | I15: Real invoice — Monin £9/L
B16: Caramel syrup (Monin) | C16: Syrup | D16: 1000 | E16: ml | F16: 5 | G16: =IFERROR(F16/D16,0) -> 0.005 | H16: ml | I16: Real invoice — Monin £9/L
B17: Salted caramel syrup (Monin) | C17: Syrup | D17: 1000 | E17: ml | F17: 5 | G17: =IFERROR(F17/D17,0) -> 0.005 | H17: ml | I17: Real invoice — Monin £9/L
... B118: Decaf coffee pod | C118: Coffee | D118: 18 | E118: unit | F118: 7.5 | G118: =IFERROR(F118/D118,0) -> 0.41666667 | H118: unit | I118: Real invoice — 18 pods = £7.50 (£0.42/pod). Use 1 pod for S, 2 for M, 3 for L.
B119: Frappe powder | C119: Specialty | D119: 1 | E119: kg | F119: 8.5 | G119: =IFERROR(F119/D119,0) -> 8.5 | H119: For milkshakes (60g per drink)
B120: Orange juice | C120: Specialty | D120: 1 | E120: L | F120: 1.5 | G120: =IFERROR(F120/D120,0) -> 1.5 | H120: Estimate — verify supplier price
G121: =IFERROR(F121/D121,0) -> 0
G122: =IFERROR(F122/D122,0) -> 0
G123: =IFERROR(F123/D123,0) -> 0
G124: =IFERROR(F124/D124,0) -> 0
G125: =IFERROR(F125/D125,0) -> 0
G126: =IFERROR(F126/D126,0) -> 0
G127: =IFERROR(F127/D127,0) -> 0
G128: =IFERROR(F128/D128,0) -> 0
G129: =IFERROR(F129/D129,0) -> 0
G130: =IFERROR(F130/D130,0) -> 0
G131: =IFERROR(F131/D131,0) -> 0
G132: =IFERROR(F132/D132,0) -> 0
... G301: =IFERROR(F301/D301,0) -> 0

Sheet Recipes
B2: Recipes — Ingredient Details per Item/Size
B3: Every item × size with its ingredients. Cost calculates from Ingredients prices via lookup. Add ingredient rows using the blank rows at the end — pick ingredient from dropdown.
B5: RECIPE SUMMARY
B6: Recipe # | C6: Item name | D6: Size | E6: Category | F6: Sell price (£) | G6: Cost price (£) | H6: Gross profit (£) | I6: Margin % | J6: # ingredients | K6: Notes | L6: Markup %
B7: 1 | C7: Banana Milkshake | D7: M | F7: 4.6 | G7: =IFERROR(SUMIFS(H328:H1942,B328:B1942,B7),0) -> 0.93991189 | H7: =F7-G7 -> 3.6600881 | I7: =IFERROR((F7-G7)/F7,0) -> 0.79567133 | J7: 5 | K7: Milkshake | L7: =IFERROR((F7-G7)/G7,0) -> 3.8940757
B8: 2 | C8: Banana Milkshake | D8: S | F8: 4.4 | G8: =IFERROR(SUMIFS(H328:H1942,B328:B1942,B8),0) -> 0.90991189 | H8: =F8-G8 -> 3.4900881 | I8: =IFERROR((F8-G8)/F8,0) -> 0.79320184 | J8: 5 | K8: Milkshake | L8: =IFERROR((F8-G8)/G8,0) -> 3.835633
B9: 3 | C9: Banana and Pecan Muffin | D9: M | F9: 3.2 | G9: =IFERROR(SUMIFS(H328:H1942,B328:B1942,B9),0) -> 1.3 | H9: =F9-G9 -> 1.9 | I9: =IFERROR((F9-G9)/F9,0) -> 0.59375 | J9: 1 | K9: Wholesale cake (CakeSmiths or similar) | L9: =IFERROR((F9-G9)/G9,0) -> 1.4615385
B10: 4 | C10: Berry Breeze Lemonade | D10: M | F10: 0 | G10: =IFERROR(SUMIFS(H328:H1942,B328:B1942,B10),0) -> 0 | H10: =F10-G10 -> 0 | I10: =IFERROR((F10-G10)/F10,0) -> 0 | J10: 4 | K10: Fruit lemonade (approx) | L10: =IFERROR((F10-G10)/G10,0) -> 0
B11: 5 | C11: Berry Breeze Lemonade | D11: S | F11: 0 | G11: =IFERROR(SUMIFS(H328:H1942,B328:B1942,B11),0) -> 0 | H11: =F11-G11 -> 0 | I11: =IFERROR((F11-G11)/F11,0) -> 0 | J11: 4 | K11: Fruit lemonade (approx) | L11: =IFERROR((F11-G11)/G11,0) -> 0
B12: 6 | C12: Berry Tea | D12: One | E12: Teas | F12: 1.9 | G12: =IFERROR(SUMIFS(H328:H1942,B328:B1942,B12),0) -> 0.199875 | H12: =F12-G12 -> 1.700125 | I12: =IFERROR((F12-G12)/F12,0) -> 0.89480263 | J12: 3 | K12: Hot tea | L12: =IFERROR((F12-G12)/G12,0) -> 8.5059412
B13: 7 | C13: Black Americano | D13: M | F13: 3.1 | G13: =IFERROR(SUMIFS(H328:H1942,B328:B1942,B13),0) -> 0.725 | H13: =F13-G13 -> 2.375 | I13: =IFERROR((F13-G13)/F13,0) -> 0.76612903 | J13: 3 | K13: Americano | L13: =IFERROR((F13-G13)/G13,0) -> 3.2758621
B14: 8 | C14: Black Americano | D14: S | F14: 2.8 | G14: =IFERROR(SUMIFS(H328:H1942,B328:B1942,B14),0) -> 0.705 | H14: =F14-G14 -> 2.095 | I14: =IFERROR((F14-G14)/F14,0) -> 0.74821429 | J14: 3 | K14: Americano | L14: =IFERROR((F14-G14)/G14,0) -> 2.9716312
B15: 9 | C15: Black Americano | D15: XL | F15: 3.4 | G15: =IFERROR(SUMIFS(H328:H1942,B328:B1942,B15),0) -> 1.34 | H15: =F15-G15 -> 2.06 | I15: =IFERROR((F15-G15)/F15,0) -> 0.60588235 | J15: 3 | K15: Americano | L15: =IFERROR((F15-G15)/G15,0) -> 1.5373134
B16: 10 | C16: Black Honey | D16: M | F16: 4 | G16: =IFERROR(SUMIFS(H328:H1942,B328:B1942,B16),0) -> 0.367875 | H16: =F16-G16 -> 3.632125 | I16: =IFERROR((F16-G16)/F16,0) -> 0.90803125 | J16: 4 | K16: Unclear — treated as tea-based drink | L16: =IFERROR((F16-G16)/G16,0) -> 9.8732586
B17: 11 | C17: Black Honey | D17: S | F17: 3.8 | G17: =IFERROR(SUMIFS(H328:H1942,B328:B1942,B17),0) -> 0.347875 | H17: =F17-G17 -> 3.452125 | I17: =IFERROR((F17-G17)/F17,0) -> 0.90845395 | J17: 4 | K17: Unclear — treated as tea-based drink | L17: =IFERROR((F17-G17)/G17,0) -> 9.9234639
B18: 12 | C18: Blue Honey Matcha | D18: M | E18: Spring saesonal drinks | F18: 4.2 | G18: =IFERROR(SUMIFS(H328:H1942,B328:B1942,B18),0) -> 0.78213363 | H18: =F18-G18 -> 3.4178664 | I18: =IFERROR((F18-G18)/F18,0) -> 0.81377771 | J18: 5 | K18: Hot matcha (blue = butterfly pea) | L18: =IFERROR((F18-G18)/G18,0) -> 4.3699264
B19: 13 | C19: Blue Honey Matcha | D19: S | E19: Spring saesonal drinks | F19: 4 | G19: =IFERROR(SUMIFS(H328:H1942,B328:B1942,B19),0) -> 0.67420411 | H19: =F19-G19 -> 3.3257959 | I19: =IFERROR((F19-G19)/F19,0) -> 0.83144897 | J19: 5 | K19: Hot matcha (blue = butterfly pea) | L19: =IFERROR((F19-G19)/G19,0) -> 4.9329214
B20: 14 | C20: Blue Honey Matcha | D20: XL | E20: Spring saesonal drinks | F20: 4.6 | G20: =IFERROR(SUMIFS(H328:H1942,B328:B1942,B20),0) -> 0.90006314 | H20: =F20-G20 -> 3.6999369 | I20: =IFERROR((F20-G20)/F20,0) -> 0.8043341 | J20: 5 | K20: Hot matcha (blue = butterfly pea) | L20: =IFERROR((F20-G20)/G20,0) -> 4.1107525
B21: 15 | C21: Blue Lavender Matcha | D21: M | E21: Spring saesonal drinks | F21: 4.2 | G21: =IFERROR(SUMIFS(H328:H1942,B328:B1942,B21),0) -> 0.76413363 | H21: =F21-G21 -> 3.4358664 | I21: =IFERROR((F21-G21)/F21,0) -> 0.81806342 | J21: 5 | K21: Hot matcha (blue = butterfly pea) | L21: =IFERROR((F21-G21)/G21,0) -> 4.4964209
B22: 16 | C22: Blue Lavender Matcha | D22: S | E22: Spring saesonal drinks | F22: 4 | G22: =IFERROR(SUMIFS(H328:H1942,B328:B1942,B22),0) -> 0.65620411 | H22: =F22-G22 -> 3.3437959 | I22: =IFERROR((F22-G22)/F22,0) -> 0.83594897 | J22: 5 | K22: Hot matcha (blue = butterfly pea) | L22: =IFERROR((F22-G22)/G22,0) -> 5.0956643
B23: 17 | C23: Blue Lavender Matcha | D23: XL | E23: Spring saesonal drinks | F23: 4.6 | G23: =IFERROR(SUMIFS(H328:H1942,B328:B1942,B23),0) -> 0.88206314 | H23: =F23-G23 -> 3.7179369 | I23: =IFERROR((F23-G23)/F23,0) -> 0.80824714 | J23: 5 | K23: Hot matcha (blue = butterfly pea) | L23: =IFERROR((F23-G23)/G23,0) -> 4.2150462
B24: 18 | C24: Blue Vanilla Matcha | D24: M | E24: Spring saesonal drinks | F24: 4.2 | G24: =IFERROR(SUMIFS(H328:H1942,B328:B1942,B24),0) -> 0.76413363 | H24: =F24-G24 -> 3.4358664 | I24: =IFERROR((F24-G24)/F24,0) -> 0.81806342 | J24: 5 | K24: Hot matcha (blue = butterfly pea) | L24: =IFERROR((F24-G24)/G24,0) -> 4.4964209
B25: 19 | C25: Blue Vanilla Matcha | D25: S | E25: Spring saesonal drinks | F25: 4 | G25: =IFERROR(SUMIFS(H328:H1942,B328:B1942,B25),0) -> 0.65620411 | H25: =F25-G25 -> 3.3437959 | I25: =IFERROR((F25-G25)/F25,0) -> 0.83594897 | J25: 5 | K25: Hot matcha (blue = butterfly pea) | L25: =IFERROR((F25-G25)/G25,0) -> 5.0956643
B26: 20 | C26: Blue Vanilla Matcha | D26: XL | E26: Spring saesonal drinks | F26: 4.6 | G26: =IFERROR(SUMIFS(H328:H1942,B328:B1942,B26),0) -> 0.88206314 | H26: =F26-G26 -> 3.7179369 | I26: =IFERROR((F26-G26)/F26,0) -> 0.80824714 | J26: 5 | K26: Hot matcha (blue = butterfly pea) | L26: =IFERROR((F26-G26)/G26,0) -> 4.2150462
B27: 21 | C27: Butterfly (lavender) Latte | D27: M | E27: Spring saesonal drinks | F27: 4.1 | G27: =IFERROR(SUMIFS(H328:H1942,B328:B1942,B27),0) -> 1.0948238 | H27: =F27-G27 -> 3.0051762 | I27: =IFERROR((F27-G27)/F27,0) -> 0.73296981 | J27: 5 | K27: Flavoured latte (Lavender syrup (Monin)) | L27: =IFERROR((F27-G27)/G27,0) -> 2.7448949
B28: 22 | C28: Butterfly (lavender) Latte | D28: S | E28: Spring saesonal drinks | F28: 3.9 | G28: =IFERROR(SUMIFS(H328:H1942,B328:B1942,B28),0) -> 0.98689427 | H28: =F28-G28 -> 2.9131057 | I28: =IFERROR((F28-G28)/F28,0) -> 0.74695019 | J28: 5 | K28: Flavoured latte (Lavender syrup (Monin)) | L28: =IFERROR((F28-G28)/G28,0) -> 2.9517911
B29: 23 | C29: Butterfly (lavender) Latte | D29: XL | E29: Spring saesonal drinks | F29: 4.3 | G29: =IFERROR(SUMIFS(H328:H1942,B328:B1942,B29),0) -> 1.7537885 | H29: =F29-G29 -> 2.5462115 | I29: =IFERROR((F29-G29)/F29,0) -> 0.5921422 | J29: 5 | K29: Flavoured latte (Lavender syrup (Monin)) | L29: =IFERROR((F29-G29)/G29,0) -> 1.4518349
B30: 24 | C30: Butterfly Hot Chocolate | D30: M | F30: 4.2 | G30: =IFERROR(SUMIFS(H328:H1942,B328:B1942,B30),0) -> 0.59913363 | H30: =F30-G30 -> 3.6008664 | I30: =IFERROR((F30-G30)/F30,0) -> 0.85734914 | J30: 4 | K30: Hot chocolate | L30: =IFERROR((F30-G30)/G30,0) -> 6.0101223
B31: 25 | C31: Butterfly Hot Chocolate | D31: S | F31: 4 | G31: =IFERROR(SUMIFS(H328:H1942,B328:B1942,B31),0) -> 0.42120411 | H31: =F31-G31 -> 3.5787959 | I31: =IFERROR((F31-G31)/F31,0) -> 0.89469897 | J31: 4 | K31: Hot chocolate | L31: =IFERROR((F31-G31)/G31,0) -> 8.4965835
B32: 26 | C32: Butterfly Hot Chocolate | D32: XL | F32: 4.4 | G32: =IFERROR(SUMIFS(H328:H1942,B328:B1942,B32),0) -> 0.78706314 | H32: =F32-G32 -> 3.6129369 | I32: =IFERROR((F32-G32)/F32,0) -> 0.82112201 | J32: 4 | K32: Hot chocolate | L32: =IFERROR((F32-G32)/G32,0) -> 4.5904028
B33: 27 | C33: Cappuccino | D33: M | F33: 3.5 | G33: =IFERROR(SUMIFS(H328:H1942,B328:B1942,B33),0) -> 0.94482379 | H33: =F33-G33 -> 2.5551762 | I33: =IFERROR((F33-G33)/F33,0) -> 0.73005035 | J33: 4 | K33: Cappuccino | L33: =IFERROR((F33-G33)/G33,0) -> 2.7043945
B34: 28 | C34: Cappuccino | D34: S | F34: 3.2 | G34: =IFERROR(SUMIFS(H328:H1942,B328:B1942,B34),0) -> 0.83689427 | H34: =F34-G34 -> 2.3631057 | I34: =IFERROR((F34-G34)/F34,0) -> 0.73847054 | J34: 4 | K34: Cappuccino | L34: =IFERROR((F34-G34)/G34,0) -> 2.823661
B35: 29 | C35: Cappuccino | D35: XL | F35: 3.8 | G35: =IFERROR(SUMIFS(H328:H1942,B328:B1942,B35),0) -> 1.6037885 | H35: =F35-G35 -> 2.1962115 | I35: =IFERROR((F35-G35)/F35,0) -> 0.57795038 | J35: 4 | K35: Cappuccino | L35: =IFERROR((F35-G35)/G35,0) -> 1.3693897
B36: 30 | C36: Chai Latte | D36: M | F36: 3.7 | G36: =IFERROR(SUMIFS(H328:H1942,B328:B1942,B36),0) -> 0.78784141 | H36: =F36-G36 -> 2.9121586 | I36: =IFERROR((F36-G36)/F36,0) -> 0.78706989 | J36: 4 | K36: Chai latte | L36: =IFERROR((F36-G36)/G36,0) -> 3.6963766
B37: 31 | C37: Chai Latte | D37: S | F37: 3.4 | G37: =IFERROR(SUMIFS(H328:H1942,B328:B1942,B37),0) -> 0.55189427 | H37: =F37-G37 -> 2.8481057 | I37: =IFERROR((F37-G37)/F37,0) -> 0.83767815 | J37: 4 | K37: Chai latte | L37: =IFERROR((F37-G37)/G37,0) -> 5.1606003
B38: 32 | C38: Chai Latte | D38: XL | F38: 4 | G38: =IFERROR(SUMIFS(H328:H1942,B328:B1942,B38),0) -> 1.0337885 | H38: =F38-G38 -> 2.9662115 | I38: =IFERROR((F38-G38)/F38,0) -> 0.74155286 | J38: 4 | K38: Chai latte | L38: =IFERROR((F38-G38)/G38,0) -> 2.8692632
B39: 33 | C39: Chocolate Coffee Milkshake | D39: M | F39: 4.6 | G39: =IFERROR(SUMIFS(H328:H1942,B328:B1942,B39),0) -> 1.2924119 | H39: =F39-G39 -> 3.3075881 | I39: =IFERROR((F39-G39)/F39,0) -> 0.71904089 | J39: 6 | K39: Milkshake | L39: =IFERROR((F39-G39)/G39,0) -> 2.5592368
B40: 34 | C40: Chocolate Coffee Milkshake | D40: S | F40: 4.4 | G40: =IFERROR(SUMIFS(H328:H1942,B328:B1942,B40),0) -> 1.2624119 | H40: =F40-G40 -> 3.1375881 | I40: =IFERROR((F40-G40)/F40,0) -> 0.71308821 | J40: 6 | K40: Milkshake | L40: =IFERROR((F40-G40)/G40,0) -> 2.4853917
B41: 35 | C41: Chocolate Milkshake | D41: M | F41: 4.6 | G41: =IFERROR(SUMIFS(H328:H1942,B328:B1942,B41),0) -> 0.99991189 | H41: =F41-G41 -> 3.6000881 | I41: =IFERROR((F41-G41)/F41,0) -> 0.78262785 | J41: 5 | K41: Milkshake | L41: =IFERROR((F41-G41)/G41,0) -> 3.6004053
B42: 36 | C42: Chocolate Milkshake | D42: S | F42: 4.2 | G42: =IFERROR(SUMIFS(H328:H1942,B328:B1942,B42),0) -> 0.96991189 | H42: =F42-G42 -> 3.2300881 | I42: =IFERROR((F42-G42)/F42,0) -> 0.7690686 | J42: 5 | K42: Milkshake | L42: =IFERROR((F42-G42)/G42,0) -> 3.3302902
...

Sheet Menu Items
B2: Menu Items — 175 Items (pulls from Recipes)
B3: Summary view. Cost prices pulled from the Recipes tab — don't edit cost here, edit the recipe.
B5: # | C5: Item name | D5: Size | E5: Category | F5: Sell price (£) | G5: Cost price (£) | H5: Margin % | I5: Square category
B6: 1 | C6: 'card' (£3.00) | D6: M | E6: Other | F6: 3 | G6: =IFERROR(VLOOKUP(279,Recipes!$B$7:$G$323,6,FALSE()),0) -> 0 | H6: =IFERROR((F6-G6)/F6,0) -> 1
B7: 2 | C7: Afternoon Deal | D7: M | E7: Meal deal | F7: 5 | G7: =IFERROR(VLOOKUP(270,Recipes!$B$7:$G$323,6,FALSE()),0) -> 0 | H7: =IFERROR((F7-G7)/F7,0) -> 1
B8: 3 | C8: Apple Juice | D8: M | E8: Bottled / pre-packed | F8: 1.6 | G8: =IFERROR(VLOOKUP(271,Recipes!$B$7:$G$323,6,FALSE()),0) -> 0 | H8: =IFERROR((F8-G8)/F8,0) -> 1
B9: 4 | C9: BKK Kyiv cake | D9: M | E9: Cake / sweet | F9: 20 | G9: =IFERROR(VLOOKUP(274,Recipes!$B$7:$G$323,6,FALSE()),0) -> 0 | H9: =IFERROR((F9-G9)/F9,0) -> 1
B10: 5 | C10: Babyccino | D10: M | E10: Other | F10: 0.5 | G10: =IFERROR(VLOOKUP(272,Recipes!$B$7:$G$323,6,FALSE()),0) -> 0 | H10: =IFERROR((F10-G10)/F10,0) -> 1
B11: 6 | C11: Banana Milkshake | D11: S | E11: Milkshake | F11: 4.4 | G11: =IFERROR(VLOOKUP(2,Recipes!$B$7:$G$323,6,FALSE()),0) -> 0.90991189 | H11: =IFERROR((F11-G11)/F11,0) -> 0.79320184
B12: 7 | C12: Banana Milkshake | D12: M | E12: Milkshake | F12: 4.6 | G12: =IFERROR(VLOOKUP(1,Recipes!$B$7:$G$323,6,FALSE()),0) -> 0.93991189 | H12: =IFERROR((F12-G12)/F12,0) -> 0.79567133
B13: 8 | C13: Banana and Pecan Muffin | D13: M | E13: Cake / sweet | F13: 3.2 | G13: =IFERROR(VLOOKUP(3,Recipes!$B$7:$G$323,6,FALSE()),0) -> 1.3 | H13: =IFERROR((F13-G13)/F13,0) -> 0.59375
B14: 9 | C14: Berry Breeze Lemonade | D14: S | E14: DISCONTINUED (May 2026) | F14: 0 | G14: =IFERROR(VLOOKUP(5,Recipes!$B$7:$G$323,6,FALSE()),0) -> 0 | H14: =IFERROR((F14-G14)/F14,0) -> 0
B15: 10 | C15: Berry Breeze Lemonade | D15: M | E15: DISCONTINUED (May 2026) | F15: 0 | G15: =IFERROR(VLOOKUP(4,Recipes!$B$7:$G$323,6,FALSE()),0) -> 0 | H15: =IFERROR((F15-G15)/F15,0) -> 0
B16: 11 | C16: Berry Tea | D16: One | E16: Tea | F16: 1.9 | G16: =IFERROR(VLOOKUP(6,Recipes!$B$7:$G$323,6,FALSE()),0) -> 0.199875 | H16: =IFERROR((F16-G16)/F16,0) -> 0.89480263 | I16: Teas
B17: 12 | C17: Billionaire's shortbread | D17: M | E17: Cake / sweet | F17: 3.6 | G17: =IFERROR(VLOOKUP(273,Recipes!$B$7:$G$323,6,FALSE()),0) -> 1.21 | H17: =IFERROR((F17-G17)/F17,0) -> 0.66388889
B18: 13 | C18: Black Americano | D18: S | E18: Americano | F18: 2.8 | G18: =IFERROR(VLOOKUP(8,Recipes!$B$7:$G$323,6,FALSE()),0) -> 0.705 | H18: =IFERROR((F18-G18)/F18,0) -> 0.74821429
B19: 14 | C19: Black Americano | D19: M | E19: Americano | F19: 3.1 | G19: =IFERROR(VLOOKUP(7,Recipes!$B$7:$G$323,6,FALSE()),0) -> 0.725 | H19: =IFERROR((F19-G19)/F19,0) -> 0.76612903
B20: 15 | C20: Black Americano | D20: XL | E20: Americano | F20: 3.4 | G20: =IFERROR(VLOOKUP(9,Recipes!$B$7:$G$323,6,FALSE()),0) -> 1.34 | H20: =IFERROR((F20-G20)/F20,0) -> 0.60588235
B21: 16 | C21: Black Honey | D21: S | E21: Tea | F21: 3.8 | G21: =IFERROR(VLOOKUP(11,Recipes!$B$7:$G$323,6,FALSE()),0) -> 0.347875 | H21: =IFERROR((F21-G21)/F21,0) -> 0.90845395
B22: 17 | C22: Black Honey | D22: M | E22: Tea | F22: 4 | G22: =IFERROR(VLOOKUP(10,Recipes!$B$7:$G$323,6,FALSE()),0) -> 0.367875 | H22: =IFERROR((F22-G22)/F22,0) -> 0.90803125
B23: 18 | C23: Blue Honey Matcha | D23: S | E23: Matcha | F23: 4 | G23: =IFERROR(VLOOKUP(13,Recipes!$B$7:$G$323,6,FALSE()),0) -> 0.67420411 | H23: =IFERROR((F23-G23)/F23,0) -> 0.83144897 | I23: Spring saesonal drinks
B24: 19 | C24: Blue Honey Matcha | D24: M | E24: Matcha | F24: 4.2 | G24: =IFERROR(VLOOKUP(12,Recipes!$B$7:$G$323,6,FALSE()),0) -> 0.78213363 | H24: =IFERROR((F24-G24)/F24,0) -> 0.81377771 | I24: Spring saesonal drinks
B25: 20 | C25: Blue Honey Matcha | D25: XL | E25: Matcha | F25: 4.6 | G25: =IFERROR(VLOOKUP(14,Recipes!$B$7:$G$323,6,FALSE()),0) -> 0.90006314 | H25: =IFERROR((F25-G25)/F25,0) -> 0.8043341 | I25: Spring saesonal drinks
B26: 21 | C26: Blue Lavender Matcha | D26: S | E26: Matcha | F26: 4 | G26: =IFERROR(VLOOKUP(16,Recipes!$B$7:$G$323,6,FALSE()),0) -> 0.65620411 | H26: =IFERROR((F26-G26)/F26,0) -> 0.83594897 | I26: Spring saesonal drinks
B27: 22 | C27: Blue Lavender Matcha | D27: M | E27: Matcha | F27: 4.2 | G27: =IFERROR(VLOOKUP(15,Recipes!$B$7:$G$323,6,FALSE()),0) -> 0.76413363 | H27: =IFERROR((F27-G27)/F27,0) -> 0.81806342 | I27: Spring saesonal drinks
B28: 23 | C28: Blue Lavender Matcha | D28: XL | E28: Matcha | F28: 4.6 | G28: =IFERROR(VLOOKUP(17,Recipes!$B$7:$G$323,6,FALSE()),0) -> 0.88206314 | H28: =IFERROR((F28-G28)/F28,0) -> 0.80824714 | I28: Spring saesonal drinks
B29: 24 | C29: Blue Vanilla Matcha | D29: S | E29: Matcha | F29: 4 | G29: =IFERROR(VLOOKUP(19,Recipes!$B$7:$G$323,6,FALSE()),0) -> 0.65620411 | H29: =IFERROR((F29-G29)/F29,0) -> 0.83594897 | I29: Spring saesonal drinks
B30: 25 | C30: Blue Vanilla Matcha | D30: M | E30: Matcha | F30: 4.2 | G30: =IFERROR(VLOOKUP(18,Recipes!$B$7:$G$323,6,FALSE()),0) -> 0.76413363 | H30: =IFERROR((F30-G30)/F30,0) -> 0.81806342 | I30: Spring saesonal drinks
B31: 26 | C31: Blue Vanilla Matcha | D31: XL | E31: Matcha | F31: 4.6 | G31: =IFERROR(VLOOKUP(20,Recipes!$B$7:$G$323,6,FALSE()),0) -> 0.88206314 | H31: =IFERROR((F31-G31)/F31,0) -> 0.80824714 | I31: Spring saesonal drinks
B32: 27 | C32: Blueberry Muffin | D32: M | E32: Cake / sweet | F32: 3.2 | G32: =IFERROR(VLOOKUP(275,Recipes!$B$7:$G$323,6,FALSE()),0) -> 1.76 | H32: =IFERROR((F32-G32)/F32,0) -> 0.45
B33: 28 | C33: Brownie Bar | D33: M | E33: Cake / sweet | F33: 2.05 | G33: =IFERROR(VLOOKUP(276,Recipes!$B$7:$G$323,6,FALSE()),0) -> 1.09 | H33: =IFERROR((F33-G33)/F33,0) -> 0.46829268
B34: 29 | C34: Butterfly (lavender) Latte | D34: S | E34: Latte / flavoured latte | F34: 3.9 | G34: =IFERROR(VLOOKUP(22,Recipes!$B$7:$G$323,6,FALSE()),0) -> 0.98689427 | H34: =IFERROR((F34-G34)/F34,0) -> 0.74695019 | I34: Spring saesonal drinks
B35: 30 | C35: Butterfly (lavender) Latte | D35: M | E35: Latte / flavoured latte | F35: 4.1 | G35: =IFERROR(VLOOKUP(21,Recipes!$B$7:$G$323,6,FALSE()),0) -> 1.0948238 | H35: =IFERROR((F35-G35)/F35,0) -> 0.73296981 | I35: Spring saesonal drinks
B36: 31 | C36: Butterfly (lavender) Latte | D36: XL | E36: Latte / flavoured latte | F36: 4.3 | G36: =IFERROR(VLOOKUP(23,Recipes!$B$7:$G$323,6,FALSE()),0) -> 1.7537885 | H36: =IFERROR((F36-G36)/F36,0) -> 0.5921422 | I36: Spring saesonal drinks
B37: 32 | C37: Butterfly Hot Chocolate | D37: S | E37: Hot chocolate | F37: 4 | G37: =IFERROR(VLOOKUP(25,Recipes!$B$7:$G$323,6,FALSE()),0) -> 0.42120411 | H37: =IFERROR((F37-G37)/F37,0) -> 0.89469897
B38: 33 | C38: Butterfly Hot Chocolate | D38: M | E38: Hot chocolate | F38: 4.2 | G38: =IFERROR(VLOOKUP(24,Recipes!$B$7:$G$323,6,FALSE()),0) -> 0.59913363 | H38: =IFERROR((F38-G38)/F38,0) -> 0.85734914
B39: 34 | C39: Butterfly Hot Chocolate | D39: XL | E39: Hot chocolate | F39: 4.4 | G39: =IFERROR(VLOOKUP(26,Recipes!$B$7:$G$323,6,FALSE()),0) -> 0.78706314 | H39: =IFERROR((F39-G39)/F39,0) -> 0.82112201
B40: 35 | C40: Cappuccino | D40: S | E40: Cappuccino | F40: 3.2 | G40: =IFERROR(VLOOKUP(28,Recipes!$B$7:$G$323,6,FALSE()),0) -> 0.83689427 | H40: =IFERROR((F40-G40)/F40,0) -> 0.73847054
B41: 36 | C41: Cappuccino | D41: M | E41: Cappuccino | F41: 3.5 | G41: =IFERROR(VLOOKUP(27,Recipes!$B$7:$G$323,6,FALSE()),0) -> 0.94482379 | H41: =IFERROR((F41-G41)/F41,0) -> 0.73005035
B42: 37 | C42: Cappuccino | D42: XL | E42: Cappuccino | F42: 3.8 | G42: =IFERROR(VLOOKUP(29,Recipes!$B$7:$G$323,6,FALSE()),0) -> 1.6037885 | H42: =IFERROR((F42-G42)/F42,0) -> 0.57795038
...

Sheet Daily Sales
B2: Daily Sales Log
B3: One row per trading day. 'Own cash' auto-fills from Cash Transactions tab if you log there. Otherwise type it in.
B5: Date | C5: Day | D5: Square — card (£) | E5: Square — cash (£) | F5: Own cash (auto from log, £) | G5: Own cash (override, £) | H5: Total revenue (£) | I5: Transactions (Square) | J5: Avg ticket (£) | K5: Notes
B6: 45901 | C6: =IFERROR(TEXT(B6,"ddd"),"") -> Mon | F6: =IFERROR(SUMIFS('Cash Transactions'!F6:F500,'Cash Transactions'!B6:B500,B6),0) -> 0 | H6: =D6+E6+IF(G6>0,G6,F6) -> 0 | J6: =IFERROR(H6/I6,0) -> 0
B7: 45902 | C7: =IFERROR(TEXT(B7,"ddd"),"") -> Tue | F7: =IFERROR(SUMIFS('Cash Transactions'!F6:F500,'Cash Transactions'!B6:B500,B7),0) -> 0 | H7: =D7+E7+IF(G7>0,G7,F7) -> 0 | J7: =IFERROR(H7/I7,0) -> 0
B8: 45903 | C8: =IFERROR(TEXT(B8,"ddd"),"") -> Wed | F8: =IFERROR(SUMIFS('Cash Transactions'!F6:F500,'Cash Transactions'!B6:B500,B8),0) -> 0 | H8: =D8+E8+IF(G8>0,G8,F8) -> 0 | J8: =IFERROR(H8/I8,0) -> 0
B9: 45904 | C9: =IFERROR(TEXT(B9,"ddd"),"") -> Thu | F9: =IFERROR(SUMIFS('Cash Transactions'!F6:F500,'Cash Transactions'!B6:B500,B9),0) -> 0 | H9: =D9+E9+IF(G9>0,G9,F9) -> 0 | J9: =IFERROR(H9/I9,0) -> 0
B10: 45905 | C10: =IFERROR(TEXT(B10,"ddd"),"") -> Fri | F10: =IFERROR(SUMIFS('Cash Transactions'!F6:F500,'Cash Transactions'!B6:B500,B10),0) -> 0 | H10: =D10+E10+IF(G10>0,G10,F10) -> 0 | J10: =IFERROR(H10/I10,0) -> 0
B11: 45906 | C11: =IFERROR(TEXT(B11,"ddd"),"") -> Sat | F11: =IFERROR(SUMIFS('Cash Transactions'!F6:F500,'Cash Transactions'!B6:B500,B11),0) -> 0 | H11: =D11+E11+IF(G11>0,G11,F11) -> 0 | J11: =IFERROR(H11/I11,0) -> 0
B12: 45907 | C12: =IFERROR(TEXT(B12,"ddd"),"") -> Sun | F12: =IFERROR(SUMIFS('Cash Transactions'!F6:F500,'Cash Transactions'!B6:B500,B12),0) -> 0 | H12: =D12+E12+IF(G12>0,G12,F12) -> 0 | J12: =IFERROR(H12/I12,0) -> 0
B13: 45908 | C13: =IFERROR(TEXT(B13,"ddd"),"") -> Mon | F13: =IFERROR(SUMIFS('Cash Transactions'!F6:F500,'Cash Transactions'!B6:B500,B13),0) -> 0 | H13: =D13+E13+IF(G13>0,G13,F13) -> 0 | J13: =IFERROR(H13/I13,0) -> 0
B14: 45909 | C14: =IFERROR(TEXT(B14,"ddd"),"") -> Tue | F14: =IFERROR(SUMIFS('Cash Transactions'!F6:F500,'Cash Transactions'!B6:B500,B14),0) -> 0 | H14: =D14+E14+IF(G14>0,G14,F14) -> 0 | J14: =IFERROR(H14/I14,0) -> 0
B15: 45910 | C15: =IFERROR(TEXT(B15,"ddd"),"") -> Wed | F15: =IFERROR(SUMIFS('Cash Transactions'!F6:F500,'Cash Transactions'!B6:B500,B15),0) -> 0 | H15: =D15+E15+IF(G15>0,G15,F15) -> 0 | J15: =IFERROR(H15/I15,0) -> 0
B16: 45911 | C16: =IFERROR(TEXT(B16,"ddd"),"") -> Thu | F16: =IFERROR(SUMIFS('Cash Transactions'!F6:F500,'Cash Transactions'!B6:B500,B16),0) -> 0 | H16: =D16+E16+IF(G16>0,G16,F16) -> 0 | J16: =IFERROR(H16/I16,0) -> 0
B17: 45912 | C17: =IFERROR(TEXT(B17,"ddd"),"") -> Fri | F17: =IFERROR(SUMIFS('Cash Transactions'!F6:F500,'Cash Transactions'!B6:B500,B17),0) -> 0 | H17: =D17+E17+IF(G17>0,G17,F17) -> 0 | J17: =IFERROR(H17/I17,0) -> 0
B18: 45913 | C18: =IFERROR(TEXT(B18,"ddd"),"") -> Sat | F18: =IFERROR(SUMIFS('Cash Transactions'!F6:F500,'Cash Transactions'!B6:B500,B18),0) -> 0 | H18: =D18+E18+IF(G18>0,G18,F18) -> 0 | J18: =IFERROR(H18/I18,0) -> 0
B19: 45914 | C19: =IFERROR(TEXT(B19,"ddd"),"") -> Sun | F19: =IFERROR(SUMIFS('Cash Transactions'!F6:F500,'Cash Transactions'!B6:B500,B19),0) -> 0 | H19: =D19+E19+IF(G19>0,G19,F19) -> 0 | J19: =IFERROR(H19/I19,0) -> 0
B20: 45915 | C20: =IFERROR(TEXT(B20,"ddd"),"") -> Mon | F20: =IFERROR(SUMIFS('Cash Transactions'!F6:F500,'Cash Transactions'!B6:B500,B20),0) -> 0 | H20: =D20+E20+IF(G20>0,G20,F20) -> 0 | J20: =IFERROR(H20/I20,0) -> 0
B21: 45916 | C21: =IFERROR(TEXT(B21,"ddd"),"") -> Tue | F21: =IFERROR(SUMIFS('Cash Transactions'!F6:F500,'Cash Transactions'!B6:B500,B21),0) -> 0 | H21: =D21+E21+IF(G21>0,G21,F21) -> 0 | J21: =IFERROR(H21/I21,0) -> 0
B22: 45917 | C22: =IFERROR(TEXT(B22,"ddd"),"") -> Wed | F22: =IFERROR(SUMIFS('Cash Transactions'!F6:F500,'Cash Transactions'!B6:B500,B22),0) -> 0 | H22: =D22+E22+IF(G22>0,G22,F22) -> 0 | J22: =IFERROR(H22/I22,0) -> 0
B23: 45918 | C23: =IFERROR(TEXT(B23,"ddd"),"") -> Thu | F23: =IFERROR(SUMIFS('Cash Transactions'!F6:F500,'Cash Transactions'!B6:B500,B23),0) -> 0 | H23: =D23+E23+IF(G23>0,G23,F23) -> 0 | J23: =IFERROR(H23/I23,0) -> 0
B24: 45919 | C24: =IFERROR(TEXT(B24,"ddd"),"") -> Fri | F24: =IFERROR(SUMIFS('Cash Transactions'!F6:F500,'Cash Transactions'!B6:B500,B24),0) -> 0 | H24: =D24+E24+IF(G24>0,G24,F24) -> 0 | J24: =IFERROR(H24/I24,0) -> 0
B25: 45920 | C25: =IFERROR(TEXT(B25,"ddd"),"") -> Sat | F25: =IFERROR(SUMIFS('Cash Transactions'!F6:F500,'Cash Transactions'!B6:B500,B25),0) -> 0 | H25: =D25+E25+IF(G25>0,G25,F25) -> 0 | J25: =IFERROR(H25/I25,0) -> 0
B26: 45921 | C26: =IFERROR(TEXT(B26,"ddd"),"") -> Sun | F26: =IFERROR(SUMIFS('Cash Transactions'!F6:F500,'Cash Transactions'!B6:B500,B26),0) -> 0 | H26: =D26+E26+IF(G26>0,G26,F26) -> 0 | J26: =IFERROR(H26/I26,0) -> 0
B27: 45922 | C27: =IFERROR(TEXT(B27,"ddd"),"") -> Mon | F27: =IFERROR(SUMIFS('Cash Transactions'!F6:F500,'Cash Transactions'!B6:B500,B27),0) -> 0 | H27: =D27+E27+IF(G27>0,G27,F27) -> 0 | J27: =IFERROR(H27/I27,0) -> 0
B28: 45923 | C28: =IFERROR(TEXT(B28,"ddd"),"") -> Tue | F28: =IFERROR(SUMIFS('Cash Transactions'!F6:F500,'Cash Transactions'!B6:B500,B28),0) -> 0 | H28: =D28+E28+IF(G28>0,G28,F28) -> 0 | J28: =IFERROR(H28/I28,0) -> 0
B29: 45924 | C29: =IFERROR(TEXT(B29,"ddd"),"") -> Wed | F29: =IFERROR(SUMIFS('Cash Transactions'!F6:F500,'Cash Transactions'!B6:B500,B29),0) -> 0 | H29: =D29+E29+IF(G29>0,G29,F29) -> 0 | J29: =IFERROR(H29/I29,0) -> 0
B30: 45925 | C30: =IFERROR(TEXT(B30,"ddd"),"") -> Thu | F30: =IFERROR(SUMIFS('Cash Transactions'!F6:F500,'Cash Transactions'!B6:B500,B30),0) -> 0 | H30: =D30+E30+IF(G30>0,G30,F30) -> 0 | J30: =IFERROR(H30/I30,0) -> 0
B31: 45926 | C31: =IFERROR(TEXT(B31,"ddd"),"") -> Fri | F31: =IFERROR(SUMIFS('Cash Transactions'!F6:F500,'Cash Transactions'!B6:B500,B31),0) -> 0 | H31: =D31+E31+IF(G31>0,G31,F31) -> 0 | J31: =IFERROR(H31/I31,0) -> 0
B32: 45927 | C32: =IFERROR(TEXT(B32,"ddd"),"") -> Sat | F32: =IFERROR(SUMIFS('Cash Transactions'!F6:F500,'Cash Transactions'!B6:B500,B32),0) -> 0 | H32: =D32+E32+IF(G32>0,G32,F32) -> 0 | J32: =IFERROR(H32/I32,0) -> 0
B33: 45928 | C33: =IFERROR(TEXT(B33,"ddd"),"") -> Sun | F33: =IFERROR(SUMIFS('Cash Transactions'!F6:F500,'Cash Transactions'!B6:B500,B33),0) -> 0 | H33: =D33+E33+IF(G33>0,G33,F33) -> 0 | J33: =IFERROR(H33/I33,0) -> 0
B34: 45929 | C34: =IFERROR(TEXT(B34,"ddd"),"") -> Mon | F34: =IFERROR(SUMIFS('Cash Transactions'!F6:F500,'Cash Transactions'!B6:B500,B34),0) -> 0 | H34: =D34+E34+IF(G34>0,G34,F34) -> 0 | J34: =IFERROR(H34/I34,0) -> 0
B35: 45930 | C35: =IFERROR(TEXT(B35,"ddd"),"") -> Tue | F35: =IFERROR(SUMIFS('Cash Transactions'!F6:F500,'Cash Transactions'!B6:B500,B35),0) -> 0 | H35: =D35+E35+IF(G35>0,G35,F35) -> 0 | J35: =IFERROR(H35/I35,0) -> 0
B36: 45931 | C36: =IFERROR(TEXT(B36,"ddd"),"") -> Wed | F36: =IFERROR(SUMIFS('Cash Transactions'!F6:F500,'Cash Transactions'!B6:B500,B36),0) -> 0 | H36: =D36+E36+IF(G36>0,G36,F36) -> 0 | J36: =IFERROR(H36/I36,0) -> 0
B37: 45932 | C37: =IFERROR(TEXT(B37,"ddd"),"") -> Thu | F37: =IFERROR(SUMIFS('Cash Transactions'!F6:F500,'Cash Transactions'!B6:B500,B37),0) -> 0 | H37: =D37+E37+IF(G37>0,G37,F37) -> 0 | J37: =IFERROR(H37/I37,0) -> 0
B38: 45933 | C38: =IFERROR(TEXT(B38,"ddd"),"") -> Fri | F38: =IFERROR(SUMIFS('Cash Transactions'!F6:F500,'Cash Transactions'!B6:B500,B38),0) -> 0 | H38: =D38+E38+IF(G38>0,G38,F38) -> 0 | J38: =IFERROR(H38/I38,0) -> 0
B39: 45934 | C39: =IFERROR(TEXT(B39,"ddd"),"") -> Sat | F39: =IFERROR(SUMIFS('Cash Transactions'!F6:F500,'Cash Transactions'!B6:B500,B39),0) -> 0 | H39: =D39+E39+IF(G39>0,G39,F39) -> 0 | J39: =IFERROR(H39/I39,0) -> 0
B40: 45935 | C40: =IFERROR(TEXT(B40,"ddd"),"") -> Sun | F40: =IFERROR(SUMIFS('Cash Transactions'!F6:F500,'Cash Transactions'!B6:B500,B40),0) -> 0 | H40: =D40+E40+IF(G40>0,G40,F40) -> 0 | J40: =IFERROR(H40/I40,0) -> 0
B41: 45936 | C41: =IFERROR(TEXT(B41,"ddd"),"") -> Mon | F41: =IFERROR(SUMIFS('Cash Transactions'!F6:F500,'Cash Transactions'!B6:B500,B41),0) -> 0 | H41: =D41+E41+IF(G41>0,G41,F41) -> 0 | J41: =IFERROR(H41/I41,0) -> 0
B42: 45937 | C42: =IFERROR(TEXT(B42,"ddd"),"") -> Tue | F42: =IFERROR(SUMIFS('Cash Transactions'!F6:F500,'Cash Transactions'!B6:B500,B42),0) -> 0 | H42: =D42+E42+IF(G42>0,G42,F42) -> 0 | J42: =IFERROR(H42/I42,0) -> 0
...

Sheet Cash Transactions
B2: Cash Transactions Log
B3: Log cash sales that didn't go through Square. Item dropdown from your menu. Totals feed Daily Sales automatically.
B5: Date | C5: Item (dropdown) | D5: Qty | E5: Unit price (£) | F5: Total (£) | G5: Notes | L5: 'card' (£3.00) (M)
F6: =IFERROR(D6*E6,0) -> 0 | L6: Afternoon Deal (M)
F7: =IFERROR(D7*E7,0) -> 0 | L7: Apple Juice (M)
F8: =IFERROR(D8*E8,0) -> 0 | L8: BKK Kyiv cake (M)
F9: =IFERROR(D9*E9,0) -> 0 | L9: Babyccino (M)
F10: =IFERROR(D10*E10,0) -> 0 | L10: Banana Milkshake (M)
F11: =IFERROR(D11*E11,0) -> 0 | L11: Banana Milkshake (S)
F12: =IFERROR(D12*E12,0) -> 0 | L12: Banana and Pecan Muffin (M)
F13: =IFERROR(D13*E13,0) -> 0 | L13: Berry Breeze Lemonade (M)
F14: =IFERROR(D14*E14,0) -> 0 | L14: Berry Breeze Lemonade (S)
F15: =IFERROR(D15*E15,0) -> 0 | L15: Berry Tea (One)
F16: =IFERROR(D16*E16,0) -> 0 | L16: Billionaire's shortbread (M)
F17: =IFERROR(D17*E17,0) -> 0 | L17: Black Americano (M)
... F318: =IFERROR(D318*E318,0) -> 0 | L318: White Mocha (XL)
F319: =IFERROR(D319*E319,0) -> 0
F320: =IFERROR(D320*E320,0) -> 0
F321: =IFERROR(D321*E321,0) -> 0
F322: =IFERROR(D322*E322,0) -> 0
F323: =IFERROR(D323*E323,0) -> 0
F324: =IFERROR(D324*E324,0) -> 0
F325: =IFERROR(D325*E325,0) -> 0
F326: =IFERROR(D326*E326,0) -> 0
F327: =IFERROR(D327*E327,0) -> 0
F328: =IFERROR(D328*E328,0) -> 0
F329: =IFERROR(D329*E329,0) -> 0
F330: =IFERROR(D330*E330,0) -> 0
... F500: =IFERROR(D500*E500,0) -> 0

Sheet Expenses
B2: Expenses Log
B3: All business outgoings. Use consistent category names — the P&L groups by these.
B5: Date | C5: Category | D5: Vendor / description | E5: Amount (£) | F5: Payment method | G5: Receipt? | H5: Notes | L5: Stock — coffee
B6: 45938 | C6: Other | D6: Nextdaycatering.co.uk Card purchase | E6: 870.78 | F6: Card | H6: Capital expenditure — Catering equipment (capital expense, not regular) | L6: Stock — dairy
B7: 45944 | C7: Other | D7: Inv-2076 Call Out Dale Morrison Bank transfer | E7: 75 | F7: Bank transfer | H7: Capital expenditure — Setup/maintenance work (capital expense) | L7: Stock — syrups
B8: 45944 | C8: Other | D8: Adexa Direct Card purchase | E8: 715.39 | F8: Card | H8: Capital expenditure — Catering equipment (capital expense, not regular) | L8: Stock — cakes
B9: 45951 | C9: Other | D9: Royal Bk Of Scotland Dundee Gbr Withdrawal | E9: 200 | F9: Cash withdrawal | H9: Director drawings — cash withdrawal | L9: Stock — food
B10: 45954 | C10: Utilities | D10: Efx076648 Everﬂow Limited Direct debit | E10: 92.13 | F10: Direct debit | H10: Water | L10: Stock — packaging
B11: 45964 | C11: Rent | D11: 23com Rent Nethergate Lettings Ltd Standing order | E11: 625 | F11: Standing order | H11: Monthly rent | L11: Stock — other
B12: 45965 | C12: Other | D12: Drem01- 44638 Chas Stewart Plumbing Heat Bank transfer | E12: 858 | F12: Bank transfer | H12: Capital expenditure — Setup/maintenance work (capital expense) | L12: Rent
B13: 45969 | C13: Utilities | D13: Bt Business Bill Card purchase | E13: 10.79 | F13: Card | H13: Phone/internet (BT) | L13: Utilities
B14: 45971 | C14: Utilities | D14: 2000322410001 Yu Energy Direct debit | E14: 39 | F14: Direct debit | H14: Electricity | L14: Wages
B15: 45978 | C15: Stock — food | D15: 2028660 Sysco Gb Direct debit | E15: 243.28 | F15: Direct debit | H15: Sysco — likely fresh food/dairy mix; could be split if needed | L15: Marketing
B16: 45984 | C16: Other | D16: Anduff Car Wash Limite Buckinghamshi Gbr Card purchase | E16: 13 | F16: Card | H16: Director drawings — Car wash — personal | L16: Square fees
B17: 45984 | C17: Stock — food | D17: Kyivsmak Card purchase | E17: 48.87 | F17: Card | H17: Kyivsmak — Ukrainian food supplier | L17: Other
B18: 45984 | C18: Stock — food | D18: Tesco Card purchase | E18: 66.8 | F18: Card | H18: Supermarket purchase — likely stock for shop
B19: 45984 | C19: Other | D19: Forfar Road Service St Scotland Card purchase | E19: 82.89 | F19: Card | H19: Director drawings — Travel — likely personal
B20: 45984 | C20: Stock — food | D20: Morrisons Daily Card purchase | E20: 41.3 | F20: Card | H20: Supermarket purchase — likely stock for shop
B21: 45984 | C21: Other | D21: Nya Scotia Forecourt S Dundee Card purchase | E21: 3 | F21: Card | H21: Director drawings — Personal
B22: 45985 | C22: Stock — food | D22: 2028660 Sysco Gb Direct debit | E22: 281.89 | F22: Direct debit | H22: Sysco — likely fresh food/dairy mix; could be split if needed
B23: 45985 | C23: Utilities | D23: Efx076648 Everﬂow Limited Direct debit | E23: 92.12 | F23: Direct debit | H23: Water
B24: 45985 | C24: Stock — food | D24: Lidl Card purchase | E24: 40.89 | F24: Card | H24: Supermarket purchase — likely stock for shop
B25: 45985 | C25: Other | D25: Dundee Cc Parking Card purchase | E25: 4 | F25: Card | H25: Director drawings — Parking — personal
B26: 45985 | C26: Other | D26: Tenpin Dundee Card purchase | E26: 18.5 | F26: Card | H26: Director drawings — Personal expenditure on business card
B27: 45985 | C27: Other | D27: David Lloyds Leisure L Dundee Card purchase | E27: 3.46 | F27: Card | H27: Director drawings — Personal expenditure on business card
B28: 45986 | C28: Stock — other | D28: Mol Ndcc Card purchase | E28: 122.91 | F28: Card | H28: Mol Ndcc — ASK USER what this is
B29: 45986 | C29: Stock — food | D29: Lidl Card purchase | E29: 48.74 | F29: Card | H29: Supermarket purchase — likely stock for shop
... B154: 46112 | C154: Stock — other | D154: Mol Ndcc Card purchase | E154: 163.62 | F154: Card | H154: Mol Ndcc — ASK USER what this is

Sheet Monthly P&L
B2: Monthly Profit & Loss — Full Year View
B3: Every month side-by-side. Change the year in yellow to see a different year. Total column auto-sums.
B5: Year: | C5: 2026
B7: Line | C7: Jan | D7: Feb | E7: Mar | F7: Apr | G7: May | H7: Jun | I7: Jul | J7: Aug | K7: Sep | L7: Oct | M7: Nov | N7: Dec | O7: TOTAL
B8: REVENUE
B9: Card sales | C9: =SUMPRODUCT((MONTH('Daily Sales'!$B$6:$B$371)=1)*(YEAR('Daily Sales'!$B$6:$B$371)=$C$5)*'Daily Sales'!$D$6:$D$371) -> 1789.8 | D9: =SUMPRODUCT((MONTH('Daily Sales'!$B$6:$B$371)=2)*(YEAR('Daily Sales'!$B$6:$B$371)=$C$5)*'Daily Sales'!$D$6:$D$371) -> 1712.7 | E9: =SUMPRODUCT((MONTH('Daily Sales'!$B$6:$B$371)=3)*(YEAR('Daily Sales'!$B$6:$B$371)=$C$5)*'Daily Sales'!$D$6:$D$371) -> 2405.44 | F9: =SUMPRODUCT((MONTH('Daily Sales'!$B$6:$B$371)=4)*(YEAR('Daily Sales'!$B$6:$B$371)=$C$5)*'Daily Sales'!$D$6:$D$371) -> 1293.05 | G9: =SUMPRODUCT((MONTH('Daily Sales'!$B$6:$B$371)=5)*(YEAR('Daily Sales'!$B$6:$B$371)=$C$5)*'Daily Sales'!$D$6:$D$371) -> 0 | H9: =SUMPRODUCT((MONTH('Daily Sales'!$B$6:$B$371)=6)*(YEAR('Daily Sales'!$B$6:$B$371)=$C$5)*'Daily Sales'!$D$6:$D$371) -> 0 | I9: =SUMPRODUCT((MONTH('Daily Sales'!$B$6:$B$371)=7)*(YEAR('Daily Sales'!$B$6:$B$371)=$C$5)*'Daily Sales'!$D$6:$D$371) -> 0 | J9: =SUMPRODUCT((MONTH('Daily Sales'!$B$6:$B$371)=8)*(YEAR('Daily Sales'!$B$6:$B$371)=$C$5)*'Daily Sales'!$D$6:$D$371) -> 0 | K9: =SUMPRODUCT((MONTH('Daily Sales'!$B$6:$B$371)=9)*(YEAR('Daily Sales'!$B$6:$B$371)=$C$5)*'Daily Sales'!$D$6:$D$371) -> 0 | L9: =SUMPRODUCT((MONTH('Daily Sales'!$B$6:$B$371)=10)*(YEAR('Daily Sales'!$B$6:$B$371)=$C$5)*'Daily Sales'!$D$6:$D$371) -> 0 | M9: =SUMPRODUCT((MONTH('Daily Sales'!$B$6:$B$371)=11)*(YEAR('Daily Sales'!$B$6:$B$371)=$C$5)*'Daily Sales'!$D$6:$D$371) -> 0 | N9: =SUMPRODUCT((MONTH('Daily Sales'!$B$6:$B$371)=12)*(YEAR('Daily Sales'!$B$6:$B$371)=$C$5)*'Daily Sales'!$D$6:$D$371) -> 0 | O9: =SUM(C9:N9) -> 7200.99
B10: Square cash sales | C10: =SUMPRODUCT((MONTH('Daily Sales'!$B$6:$B$371)=1)*(YEAR('Daily Sales'!$B$6:$B$371)=$C$5)*'Daily Sales'!$E$6:$E$371) -> 17.73 | D10: =SUMPRODUCT((MONTH('Daily Sales'!$B$6:$B$371)=2)*(YEAR('Daily Sales'!$B$6:$B$371)=$C$5)*'Daily Sales'!$E$6:$E$371) -> 20.12 | E10: =SUMPRODUCT((MONTH('Daily Sales'!$B$6:$B$371)=3)*(YEAR('Daily Sales'!$B$6:$B$371)=$C$5)*'Daily Sales'!$E$6:$E$371) -> 31.77 | F10: =SUMPRODUCT((MONTH('Daily Sales'!$B$6:$B$371)=4)*(YEAR('Daily Sales'!$B$6:$B$371)=$C$5)*'Daily Sales'!$E$6:$E$371) -> 0 | G10: =SUMPRODUCT((MONTH('Daily Sales'!$B$6:$B$371)=5)*(YEAR('Daily Sales'!$B$6:$B$371)=$C$5)*'Daily Sales'!$E$6:$E$371) -> 0 | H10: =SUMPRODUCT((MONTH('Daily Sales'!$B$6:$B$371)=6)*(YEAR('Daily Sales'!$B$6:$B$371)=$C$5)*'Daily Sales'!$E$6:$E$371) -> 0 | I10: =SUMPRODUCT((MONTH('Daily Sales'!$B$6:$B$371)=7)*(YEAR('Daily Sales'!$B$6:$B$371)=$C$5)*'Daily Sales'!$E$6:$E$371) -> 0 | J10: =SUMPRODUCT((MONTH('Daily Sales'!$B$6:$B$371)=8)*(YEAR('Daily Sales'!$B$6:$B$371)=$C$5)*'Daily Sales'!$E$6:$E$371) -> 0 | K10: =SUMPRODUCT((MONTH('Daily Sales'!$B$6:$B$371)=9)*(YEAR('Daily Sales'!$B$6:$B$371)=$C$5)*'Daily Sales'!$E$6:$E$371) -> 0 | L10: =SUMPRODUCT((MONTH('Daily Sales'!$B$6:$B$371)=10)*(YEAR('Daily Sales'!$B$6:$B$371)=$C$5)*'Daily Sales'!$E$6:$E$371) -> 0 | M10: =SUMPRODUCT((MONTH('Daily Sales'!$B$6:$B$371)=11)*(YEAR('Daily Sales'!$B$6:$B$371)=$C$5)*'Daily Sales'!$E$6:$E$371) -> 0 | N10: =SUMPRODUCT((MONTH('Daily Sales'!$B$6:$B$371)=12)*(YEAR('Daily Sales'!$B$6:$B$371)=$C$5)*'Daily Sales'!$E$6:$E$371) -> 0 | O10: =SUM(C10:N10) -> 69.62
B11: Own cash sales | C11: =SUMPRODUCT((MONTH('Daily Sales'!$B$6:$B$371)=1)*(YEAR('Daily Sales'!$B$6:$B$371)=$C$5)*IF('Daily Sales'!$G$6:$G$371>0,'Daily Sales'!$G$6:$G$371,'Daily Sales'!$F$6:$F$371)) -> 0 | D11: =SUMPRODUCT((MONTH('Daily Sales'!$B$6:$B$371)=2)*(YEAR('Daily Sales'!$B$6:$B$371)=$C$5)*IF('Daily Sales'!$G$6:$G$371>0,'Daily Sales'!$G$6:$G$371,'Daily Sales'!$F$6:$F$371)) -> 0 | E11: =SUMPRODUCT((MONTH('Daily Sales'!$B$6:$B$371)=3)*(YEAR('Daily Sales'!$B$6:$B$371)=$C$5)*IF('Daily Sales'!$G$6:$G$371>0,'Daily Sales'!$G$6:$G$371,'Daily Sales'!$F$6:$F$371)) -> 0 | F11: =SUMPRODUCT((MONTH('Daily Sales'!$B$6:$B$371)=4)*(YEAR('Daily Sales'!$B$6:$B$371)=$C$5)*IF('Daily Sales'!$G$6:$G$371>0,'Daily Sales'!$G$6:$G$371,'Daily Sales'!$F$6:$F$371)) -> 0 | G11: =SUMPRODUCT((MONTH('Daily Sales'!$B$6:$B$371)=5)*(YEAR('Daily Sales'!$B$6:$B$371)=$C$5)*IF('Daily Sales'!$G$6:$G$371>0,'Daily Sales'!$G$6:$G$371,'Daily Sales'!$F$6:$F$371)) -> 0 | H11: =SUMPRODUCT((MONTH('Daily Sales'!$B$6:$B$371)=6)*(YEAR('Daily Sales'!$B$6:$B$371)=$C$5)*IF('Daily Sales'!$G$6:$G$371>0,'Daily Sales'!$G$6:$G$371,'Daily Sales'!$F$6:$F$371)) -> 0 | I11: =SUMPRODUCT((MONTH('Daily Sales'!$B$6:$B$371)=7)*(YEAR('Daily Sales'!$B$6:$B$371)=$C$5)*IF('Daily Sales'!$G$6:$G$371>0,'Daily Sales'!$G$6:$G$371,'Daily Sales'!$F$6:$F$371)) -> 0 | J11: =SUMPRODUCT((MONTH('Daily Sales'!$B$6:$B$371)=8)*(YEAR('Daily Sales'!$B$6:$B$371)=$C$5)*IF('Daily Sales'!$G$6:$G$371>0,'Daily Sales'!$G$6:$G$371,'Daily Sales'!$F$6:$F$371)) -> 0 | K11: =SUMPRODUCT((MONTH('Daily Sales'!$B$6:$B$371)=9)*(YEAR('Daily Sales'!$B$6:$B$371)=$C$5)*IF('Daily Sales'!$G$6:$G$371>0,'Daily Sales'!$G$6:$G$371,'Daily Sales'!$F$6:$F$371)) -> 0 | L11: =SUMPRODUCT((MONTH('Daily Sales'!$B$6:$B$371)=10)*(YEAR('Daily Sales'!$B$6:$B$371)=$C$5)*IF('Daily Sales'!$G$6:$G$371>0,'Daily Sales'!$G$6:$G$371,'Daily Sales'!$F$6:$F$371)) -> 0 | M11: =SUMPRODUCT((MONTH('Daily Sales'!$B$6:$B$371)=11)*(YEAR('Daily Sales'!$B$6:$B$371)=$C$5)*IF('Daily Sales'!$G$6:$G$371>0,'Daily Sales'!$G$6:$G$371,'Daily Sales'!$F$6:$F$371)) -> 0 | N11: =SUMPRODUCT((MONTH('Daily Sales'!$B$6:$B$371)=12)*(YEAR('Daily Sales'!$B$6:$B$371)=$C$5)*IF('Daily Sales'!$G$6:$G$371>0,'Daily Sales'!$G$6:$G$371,'Daily Sales'!$F$6:$F$371)) -> 0 | O11: =SUM(C11:N11) -> 0
B12: TOTAL REVENUE | C12: =C9+C10+C11 -> 1807.53 | D12: =D9+D10+D11 -> 1732.82 | E12: =E9+E10+E11 -> 2437.21 | F12: =F9+F10+F11 -> 1293.05 | G12: =G9+G10+G11 -> 0 | H12: =H9+H10+H11 -> 0 | I12: =I9+I10+I11 -> 0 | J12: =J9+J10+J11 -> 0 | ... N12: =N9+N10+N11 -> 0 | O12: =SUM(C12:N12) -> 7270.61
B14: COST OF GOODS SOLD
B15: Stock — coffee | C15: =SUMPRODUCT((MONTH(Expenses!$B$6:$B$500)=1)*(YEAR(Expenses!$B$6:$B$500)=$C$5)*(Expenses!$C$6:$C$500="Stock — coffee")*Expenses!$E$6:$E$500) -> 38 | D15: =SUMPRODUCT((MONTH(Expenses!$B$6:$B$500)=2)*(YEAR(Expenses!$B$6:$B$500)=$C$5)*(Expenses!$C$6:$C$500="Stock — coffee")*Expenses!$E$6:$E$500) -> 114 | E15: =SUMPRODUCT((MONTH(Expenses!$B$6:$B$500)=3)*(YEAR(Expenses!$B$6:$B$500)=$C$5)*(Expenses!$C$6:$C$500="Stock — coffee")*Expenses!$E$6:$E$500) -> 76 | F15: =SUMPRODUCT((MONTH(Expenses!$B$6:$B$500)=4)*(YEAR(Expenses!$B$6:$B$500)=$C$5)*(Expenses!$C$6:$C$500="Stock — coffee")*Expenses!$E$6:$E$500) -> 0 | G15: =SUMPRODUCT((MONTH(Expenses!$B$6:$B$500)=5)*(YEAR(Expenses!$B$6:$B$500)=$C$5)*(Expenses!$C$6:$C$500="Stock — coffee")*Expenses!$E$6:$E$500) -> 0 | H15: =SUMPRODUCT((MONTH(Expenses!$B$6:$B$500)=6)*(YEAR(Expenses!$B$6:$B$500)=$C$5)*(Expenses!$C$6:$C$500="Stock — coffee")*Expenses!$E$6:$E$500) -> 0 | I15: =SUMPRODUCT((MONTH(Expenses!$B$6:$B$500)=7)*(YEAR(Expenses!$B$6:$B$500)=$C$5)*(Expenses!$C$6:$C$500="Stock — coffee")*Expenses!$E$6:$E$500) -> 0 | J15: =SUMPRODUCT((MONTH(Expenses!$B$6:$B$500)=8)*(YEAR(Expenses!$B$6:$B$500)=$C$5)*(Expenses!$C$6:$C$500="Stock — coffee")*Expenses!$E$6:$E$500) -> 0 | K15: =SUMPRODUCT((MONTH(Expenses!$B$6:$B$500)=9)*(YEAR(Expenses!$B$6:$B$500)=$C$5)*(Expenses!$C$6:$C$500="Stock — coffee")*Expenses!$E$6:$E$500) -> 0 | L15: =SUMPRODUCT((MONTH(Expenses!$B$6:$B$500)=10)*(YEAR(Expenses!$B$6:$B$500)=$C$5)*(Expenses!$C$6:$C$500="Stock — coffee")*Expenses!$E$6:$E$500) -> 0 | M15: =SUMPRODUCT((MONTH(Expenses!$B$6:$B$500)=11)*(YEAR(Expenses!$B$6:$B$500)=$C$5)*(Expenses!$C$6:$C$500="Stock — coffee")*Expenses!$E$6:$E$500) -> 0 | N15: =SUMPRODUCT((MONTH(Expenses!$B$6:$B$500)=12)*(YEAR(Expenses!$B$6:$B$500)=$C$5)*(Expenses!$C$6:$C$500="Stock — coffee")*Expenses!$E$6:$E$500) -> 0 | O15: =SUM(C15:N15) -> 228
B16: Stock — dairy | C16: =SUMPRODUCT((MONTH(Expenses!$B$6:$B$500)=1)*(YEAR(Expenses!$B$6:$B$500)=$C$5)*(Expenses!$C$6:$C$500="Stock — dairy")*Expenses!$E$6:$E$500) -> 0 | D16: =SUMPRODUCT((MONTH(Expenses!$B$6:$B$500)=2)*(YEAR(Expenses!$B$6:$B$500)=$C$5)*(Expenses!$C$6:$C$500="Stock — dairy")*Expenses!$E$6:$E$500) -> 0 | E16: =SUMPRODUCT((MONTH(Expenses!$B$6:$B$500)=3)*(YEAR(Expenses!$B$6:$B$500)=$C$5)*(Expenses!$C$6:$C$500="Stock — dairy")*Expenses!$E$6:$E$500) -> 0 | F16: =SUMPRODUCT((MONTH(Expenses!$B$6:$B$500)=4)*(YEAR(Expenses!$B$6:$B$500)=$C$5)*(Expenses!$C$6:$C$500="Stock — dairy")*Expenses!$E$6:$E$500) -> 0 | G16: =SUMPRODUCT((MONTH(Expenses!$B$6:$B$500)=5)*(YEAR(Expenses!$B$6:$B$500)=$C$5)*(Expenses!$C$6:$C$500="Stock — dairy")*Expenses!$E$6:$E$500) -> 0 | H16: =SUMPRODUCT((MONTH(Expenses!$B$6:$B$500)=6)*(YEAR(Expenses!$B$6:$B$500)=$C$5)*(Expenses!$C$6:$C$500="Stock — dairy")*Expenses!$E$6:$E$500) -> 0 | I16: =SUMPRODUCT((MONTH(Expenses!$B$6:$B$500)=7)*(YEAR(Expenses!$B$6:$B$500)=$C$5)*(Expenses!$C$6:$C$500="Stock — dairy")*Expenses!$E$6:$E$500) -> 0 | J16: =SUMPRODUCT((MONTH(Expenses!$B$6:$B$500)=8)*(YEAR(Expenses!$B$6:$B$500)=$C$5)*(Expenses!$C$6:$C$500="Stock — dairy")*Expenses!$E$6:$E$500) -> 0 | K16: =SUMPRODUCT((MONTH(Expenses!$B$6:$B$500)=9)*(YEAR(Expenses!$B$6:$B$500)=$C$5)*(Expenses!$C$6:$C$500="Stock — dairy")*Expenses!$E$6:$E$500) -> 0 | L16: =SUMPRODUCT((MONTH(Expenses!$B$6:$B$500)=10)*(YEAR(Expenses!$B$6:$B$500)=$C$5)*(Expenses!$C$6:$C$500="Stock — dairy")*Expenses!$E$6:$E$500) -> 0 | M16: =SUMPRODUCT((MONTH(Expenses!$B$6:$B$500)=11)*(YEAR(Expenses!$B$6:$B$500)=$C$5)*(Expenses!$C$6:$C$500="Stock — dairy")*Expenses!$E$6:$E$500) -> 0 | N16: =SUMPRODUCT((MONTH(Expenses!$B$6:$B$500)=12)*(YEAR(Expenses!$B$6:$B$500)=$C$5)*(Expenses!$C$6:$C$500="Stock — dairy")*Expenses!$E$6:$E$500) -> 0 | O16: =SUM(C16:N16) -> 0
B17: Stock — syrups | C17: =SUMPRODUCT((MONTH(Expenses!$B$6:$B$500)=1)*(YEAR(Expenses!$B$6:$B$500)=$C$5)*(Expenses!$C$6:$C$500="Stock — syrups")*Expenses!$E$6:$E$500) -> 0 | D17: =SUMPRODUCT((MONTH(Expenses!$B$6:$B$500)=2)*(YEAR(Expenses!$B$6:$B$500)=$C$5)*(Expenses!$C$6:$C$500="Stock — syrups")*Expenses!$E$6:$E$500) -> 0 | E17: =SUMPRODUCT((MONTH(Expenses!$B$6:$B$500)=3)*(YEAR(Expenses!$B$6:$B$500)=$C$5)*(Expenses!$C$6:$C$500="Stock — syrups")*Expenses!$E$6:$E$500) -> 0 | F17: =SUMPRODUCT((MONTH(Expenses!$B$6:$B$500)=4)*(YEAR(Expenses!$B$6:$B$500)=$C$5)*(Expenses!$C$6:$C$500="Stock — syrups")*Expenses!$E$6:$E$500) -> 0 | G17: =SUMPRODUCT((MONTH(Expenses!$B$6:$B$500)=5)*(YEAR(Expenses!$B$6:$B$500)=$C$5)*(Expenses!$C$6:$C$500="Stock — syrups")*Expenses!$E$6:$E$500) -> 0 | H17: =SUMPRODUCT((MONTH(Expenses!$B$6:$B$500)=6)*(YEAR(Expenses!$B$6:$B$500)=$C$5)*(Expenses!$C$6:$C$500="Stock — syrups")*Expenses!$E$6:$E$500) -> 0 | I17: =SUMPRODUCT((MONTH(Expenses!$B$6:$B$500)=7)*(YEAR(Expenses!$B$6:$B$500)=$C$5)*(Expenses!$C$6:$C$500="Stock — syrups")*Expenses!$E$6:$E$500) -> 0 | J17: =SUMPRODUCT((MONTH(Expenses!$B$6:$B$500)=8)*(YEAR(Expenses!$B$6:$B$500)=$C$5)*(Expenses!$C$6:$C$500="Stock — syrups")*Expenses!$E$6:$E$500) -> 0 | K17: =SUMPRODUCT((MONTH(Expenses!$B$6:$B$500)=9)*(YEAR(Expenses!$B$6:$B$500)=$C$5)*(Expenses!$C$6:$C$500="Stock — syrups")*Expenses!$E$6:$E$500) -> 0 | L17: =SUMPRODUCT((MONTH(Expenses!$B$6:$B$500)=10)*(YEAR(Expenses!$B$6:$B$500)=$C$5)*(Expenses!$C$6:$C$500="Stock — syrups")*Expenses!$E$6:$E$500) -> 0 | M17: =SUMPRODUCT((MONTH(Expenses!$B$6:$B$500)=11)*(YEAR(Expenses!$B$6:$B$500)=$C$5)*(Expenses!$C$6:$C$500="Stock — syrups")*Expenses!$E$6:$E$500) -> 0 | N17: =SUMPRODUCT((MONTH(Expenses!$B$6:$B$500)=12)*(YEAR(Expenses!$B$6:$B$500)=$C$5)*(Expenses!$C$6:$C$500="Stock — syrups")*Expenses!$E$6:$E$500) -> 0 | O17: =SUM(C17:N17) -> 0
B18: Stock — cakes | C18: =SUMPRODUCT((MONTH(Expenses!$B$6:$B$500)=1)*(YEAR(Expenses!$B$6:$B$500)=$C$5)*(Expenses!$C$6:$C$500="Stock — cakes")*Expenses!$E$6:$E$500) -> 0 | D18: =SUMPRODUCT((MONTH(Expenses!$B$6:$B$500)=2)*(YEAR(Expenses!$B$6:$B$500)=$C$5)*(Expenses!$C$6:$C$500="Stock — cakes")*Expenses!$E$6:$E$500) -> 0 | E18: =SUMPRODUCT((MONTH(Expenses!$B$6:$B$500)=3)*(YEAR(Expenses!$B$6:$B$500)=$C$5)*(Expenses!$C$6:$C$500="Stock — cakes")*Expenses!$E$6:$E$500) -> 0 | F18: =SUMPRODUCT((MONTH(Expenses!$B$6:$B$500)=4)*(YEAR(Expenses!$B$6:$B$500)=$C$5)*(Expenses!$C$6:$C$500="Stock — cakes")*Expenses!$E$6:$E$500) -> 0 | G18: =SUMPRODUCT((MONTH(Expenses!$B$6:$B$500)=5)*(YEAR(Expenses!$B$6:$B$500)=$C$5)*(Expenses!$C$6:$C$500="Stock — cakes")*Expenses!$E$6:$E$500) -> 0 | H18: =SUMPRODUCT((MONTH(Expenses!$B$6:$B$500)=6)*(YEAR(Expenses!$B$6:$B$500)=$C$5)*(Expenses!$C$6:$C$500="Stock — cakes")*Expenses!$E$6:$E$500) -> 0 | I18: =SUMPRODUCT((MONTH(Expenses!$B$6:$B$500)=7)*(YEAR(Expenses!$B$6:$B$500)=$C$5)*(Expenses!$C$6:$C$500="Stock — cakes")*Expenses!$E$6:$E$500) -> 0 | J18: =SUMPRODUCT((MONTH(Expenses!$B$6:$B$500)=8)*(YEAR(Expenses!$B$6:$B$500)=$C$5)*(Expenses!$C$6:$C$500="Stock — cakes")*Expenses!$E$6:$E$500) -> 0 | K18: =SUMPRODUCT((MONTH(Expenses!$B$6:$B$500)=9)*(YEAR(Expenses!$B$6:$B$500)=$C$5)*(Expenses!$C$6:$C$500="Stock — cakes")*Expenses!$E$6:$E$500) -> 0 | L18: =SUMPRODUCT((MONTH(Expenses!$B$6:$B$500)=10)*(YEAR(Expenses!$B$6:$B$500)=$C$5)*(Expenses!$C$6:$C$500="Stock — cakes")*Expenses!$E$6:$E$500) -> 0 | M18: =SUMPRODUCT((MONTH(Expenses!$B$6:$B$500)=11)*(YEAR(Expenses!$B$6:$B$500)=$C$5)*(Expenses!$C$6:$C$500="Stock — cakes")*Expenses!$E$6:$E$500) -> 0 | N18: =SUMPRODUCT((MONTH(Expenses!$B$6:$B$500)=12)*(YEAR(Expenses!$B$6:$B$500)=$C$5)*(Expenses!$C$6:$C$500="Stock — cakes")*Expenses!$E$6:$E$500) -> 0 | O18: =SUM(C18:N18) -> 0
B19: Stock — food | C19: =SUMPRODUCT((MONTH(Expenses!$B$6:$B$500)=1)*(YEAR(Expenses!$B$6:$B$500)=$C$5)*(Expenses!$C$6:$C$500="Stock — food")*Expenses!$E$6:$E$500) -> 462.16 | D19: =SUMPRODUCT((MONTH(Expenses!$B$6:$B$500)=2)*(YEAR(Expenses!$B$6:$B$500)=$C$5)*(Expenses!$C$6:$C$500="Stock — food")*Expenses!$E$6:$E$500) -> 375.18 | E19: =SUMPRODUCT((MONTH(Expenses!$B$6:$B$500)=3)*(YEAR(Expenses!$B$6:$B$500)=$C$5)*(Expenses!$C$6:$C$500="Stock — food")*Expenses!$E$6:$E$500) -> 410.48 | F19: =SUMPRODUCT((MONTH(Expenses!$B$6:$B$500)=4)*(YEAR(Expenses!$B$6:$B$500)=$C$5)*(Expenses!$C$6:$C$500="Stock — food")*Expenses!$E$6:$E$500) -> 0 | G19: =SUMPRODUCT((MONTH(Expenses!$B$6:$B$500)=5)*(YEAR(Expenses!$B$6:$B$500)=$C$5)*(Expenses!$C$6:$C$500="Stock — food")*Expenses!$E$6:$E$500) -> 0 | H19: =SUMPRODUCT((MONTH(Expenses!$B$6:$B$500)=6)*(YEAR(Expenses!$B$6:$B$500)=$C$5)*(Expenses!$C$6:$C$500="Stock — food")*Expenses!$E$6:$E$500) -> 0 | I19: =SUMPRODUCT((MONTH(Expenses!$B$6:$B$500)=7)*(YEAR(Expenses!$B$6:$B$500)=$C$5)*(Expenses!$C$6:$C$500="Stock — food")*Expenses!$E$6:$E$500) -> 0 | J19: =SUMPRODUCT((MONTH(Expenses!$B$6:$B$500)=8)*(YEAR(Expenses!$B$6:$B$500)=$C$5)*(Expenses!$C$6:$C$500="Stock — food")*Expenses!$E$6:$E$500) -> 0 | K19: =SUMPRODUCT((MONTH(Expenses!$B$6:$B$500)=9)*(YEAR(Expenses!$B$6:$B$500)=$C$5)*(Expenses!$C$6:$C$500="Stock — food")*Expenses!$E$6:$E$500) -> 0 | L19: =SUMPRODUCT((MONTH(Expenses!$B$6:$B$500)=10)*(YEAR(Expenses!$B$6:$B$500)=$C$5)*(Expenses!$C$6:$C$500="Stock — food")*Expenses!$E$6:$E$500) -> 0 | M19: =SUMPRODUCT((MONTH(Expenses!$B$6:$B$500)=11)*(YEAR(Expenses!$B$6:$B$500)=$C$5)*(Expenses!$C$6:$C$500="Stock — food")*Expenses!$E$6:$E$500) -> 0 | N19: =SUMPRODUCT((MONTH(Expenses!$B$6:$B$500)=12)*(YEAR(Expenses!$B$6:$B$500)=$C$5)*(Expenses!$C$6:$C$500="Stock — food")*Expenses!$E$6:$E$500) -> 0 | O19: =SUM(C19:N19) -> 1247.82
B20: Stock — packaging | C20: =SUMPRODUCT((MONTH(Expenses!$B$6:$B$500)=1)*(YEAR(Expenses!$B$6:$B$500)=$C$5)*(Expenses!$C$6:$C$500="Stock — packaging")*Expenses!$E$6:$E$500) -> 0 | D20: =SUMPRODUCT((MONTH(Expenses!$B$6:$B$500)=2)*(YEAR(Expenses!$B$6:$B$500)=$C$5)*(Expenses!$C$6:$C$500="Stock — packaging")*Expenses!$E$6:$E$500) -> 0 | E20: =SUMPRODUCT((MONTH(Expenses!$B$6:$B$500)=3)*(YEAR(Expenses!$B$6:$B$500)=$C$5)*(Expenses!$C$6:$C$500="Stock — packaging")*Expenses!$E$6:$E$500) -> 0 | F20: =SUMPRODUCT((MONTH(Expenses!$B$6:$B$500)=4)*(YEAR(Expenses!$B$6:$B$500)=$C$5)*(Expenses!$C$6:$C$500="Stock — packaging")*Expenses!$E$6:$E$500) -> 0 | G20: =SUMPRODUCT((MONTH(Expenses!$B$6:$B$500)=5)*(YEAR(Expenses!$B$6:$B$500)=$C$5)*(Expenses!$C$6:$C$500="Stock — packaging")*Expenses!$E$6:$E$500) -> 0 | H20: =SUMPRODUCT((MONTH(Expenses!$B$6:$B$500)=6)*(YEAR(Expenses!$B$6:$B$500)=$C$5)*(Expenses!$C$6:$C$500="Stock — packaging")*Expenses!$E$6:$E$500) -> 0 | I20: =SUMPRODUCT((MONTH(Expenses!$B$6:$B$500)=7)*(YEAR(Expenses!$B$6:$B$500)=$C$5)*(Expenses!$C$6:$C$500="Stock — packaging")*Expenses!$E$6:$E$500) -> 0 | J20: =SUMPRODUCT((MONTH(Expenses!$B$6:$B$500)=8)*(YEAR(Expenses!$B$6:$B$500)=$C$5)*(Expenses!$C$6:$C$500="Stock — packaging")*Expenses!$E$6:$E$500) -> 0 | K20: =SUMPRODUCT((MONTH(Expenses!$B$6:$B$500)=9)*(YEAR(Expenses!$B$6:$B$500)=$C$5)*(Expenses!$C$6:$C$500="Stock — packaging")*Expenses!$E$6:$E$500) -> 0 | L20: =SUMPRODUCT((MONTH(Expenses!$B$6:$B$500)=10)*(YEAR(Expenses!$B$6:$B$500)=$C$5)*(Expenses!$C$6:$C$500="Stock — packaging")*Expenses!$E$6:$E$500) -> 0 | M20: =SUMPRODUCT((MONTH(Expenses!$B$6:$B$500)=11)*(YEAR(Expenses!$B$6:$B$500)=$C$5)*(Expenses!$C$6:$C$500="Stock — packaging")*Expenses!$E$6:$E$500) -> 0 | N20: =SUMPRODUCT((MONTH(Expenses!$B$6:$B$500)=12)*(YEAR(Expenses!$B$6:$B$500)=$C$5)*(Expenses!$C$6:$C$500="Stock — packaging")*Expenses!$E$6:$E$500) -> 0 | O20: =SUM(C20:N20) -> 0
B21: Stock — other | C21: =SUMPRODUCT((MONTH(Expenses!$B$6:$B$500)=1)*(YEAR(Expenses!$B$6:$B$500)=$C$5)*(Expenses!$C$6:$C$500="Stock — other")*Expenses!$E$6:$E$500) -> 560.17 | D21: =SUMPRODUCT((MONTH(Expenses!$B$6:$B$500)=2)*(YEAR(Expenses!$B$6:$B$500)=$C$5)*(Expenses!$C$6:$C$500="Stock — other")*Expenses!$E$6:$E$500) -> 309.16 | E21: =SUMPRODUCT((MONTH(Expenses!$B$6:$B$500)=3)*(YEAR(Expenses!$B$6:$B$500)=$C$5)*(Expenses!$C$6:$C$500="Stock — other")*Expenses!$E$6:$E$500) -> 393.07 | F21: =SUMPRODUCT((MONTH(Expenses!$B$6:$B$500)=4)*(YEAR(Expenses!$B$6:$B$500)=$C$5)*(Expenses!$C$6:$C$500="Stock — other")*Expenses!$E$6:$E$500) -> 0 | G21: =SUMPRODUCT((MONTH(Expenses!$B$6:$B$500)=5)*(YEAR(Expenses!$B$6:$B$500)=$C$5)*(Expenses!$C$6:$C$500="Stock — other")*Expenses!$E$6:$E$500) -> 0 | H21: =SUMPRODUCT((MONTH(Expenses!$B$6:$B$500)=6)*(YEAR(Expenses!$B$6:$B$500)=$C$5)*(Expenses!$C$6:$C$500="Stock — other")*Expenses!$E$6:$E$500) -> 0 | I21: =SUMPRODUCT((MONTH(Expenses!$B$6:$B$500)=7)*(YEAR(Expenses!$B$6:$B$500)=$C$5)*(Expenses!$C$6:$C$500="Stock — other")*Expenses!$E$6:$E$500) -> 0 | J21: =SUMPRODUCT((MONTH(Expenses!$B$6:$B$500)=8)*(YEAR(Expenses!$B$6:$B$500)=$C$5)*(Expenses!$C$6:$C$500="Stock — other")*Expenses!$E$6:$E$500) -> 0 | K21: =SUMPRODUCT((MONTH(Expenses!$B$6:$B$500)=9)*(YEAR(Expenses!$B$6:$B$500)=$C$5)*(Expenses!$C$6:$C$500="Stock — other")*Expenses!$E$6:$E$500) -> 0 | L21: =SUMPRODUCT((MONTH(Expenses!$B$6:$B$500)=10)*(YEAR(Expenses!$B$6:$B$500)=$C$5)*(Expenses!$C$6:$C$500="Stock — other")*Expenses!$E$6:$E$500) -> 0 | M21: =SUMPRODUCT((MONTH(Expenses!$B$6:$B$500)=11)*(YEAR(Expenses!$B$6:$B$500)=$C$5)*(Expenses!$C$6:$C$500="Stock — other")*Expenses!$E$6:$E$500) -> 0 | N21: =SUMPRODUCT((MONTH(Expenses!$B$6:$B$500)=12)*(YEAR(Expenses!$B$6:$B$500)=$C$5)*(Expenses!$C$6:$C$500="Stock — other")*Expenses!$E$6:$E$500) -> 0 | O21: =SUM(C21:N21) -> 1262.4
B22: TOTAL COGS | C22: =SUM(C15:C21) -> 1060.33 | D22: =SUM(D15:D21) -> 798.34 | E22: =SUM(E15:E21) -> 879.55 | F22: =SUM(F15:F21) -> 0 | G22: =SUM(G15:G21) -> 0 | H22: =SUM(H15:H21) -> 0 | I22: =SUM(I15:I21) -> 0 | J22: =SUM(J15:J21) -> 0 | ... N22: =SUM(N15:N21) -> 0 | O22: =SUM(C22:N22) -> 2738.22
B24: GROSS PROFIT | C24: =C12-C22 -> 747.2 | D24: =D12-D22 -> 934.48 | E24: =E12-E22 -> 1557.66 | F24: =F12-F22 -> 1293.05 | G24: =G12-G22 -> 0 | H24: =H12-H22 -> 0 | I24: =I12-I22 -> 0 | J24: =J12-J22 -> 0 | ... N24: =N12-N22 -> 0 | O24: =SUM(C24:N24) -> 4532.39
B25: Gross margin % | C25: =IFERROR(C24/C12,0) -> 0.4133818 | D25: =IFERROR(D24/D12,0) -> 0.53928279 | E25: =IFERROR(E24/E12,0) -> 0.63911604 | F25: =IFERROR(F24/F12,0) -> 1 | G25: =IFERROR(G24/G12,0) -> 0 | H25: =IFERROR(H24/H12,0) -> 0 | I25: =IFERROR(I24/I12,0) -> 0 | J25: =IFERROR(J24/J12,0) -> 0 | ... N25: =IFERROR(N24/N12,0) -> 0 | O25: =IFERROR(AVERAGE(C25:N25),0) -> 0.21598172
B27: OPERATING EXPENSES
